Workbook

Sheet 月度汇总
A1: 月份 | B1: 已完成 | C1: 未完成 | D1: 完成率
A2: 2026-10 | B2: =COUNTIF('2026-10'!D2:D1000,"☑ 已完成") | C2: =COUNTIF('2026-10'!D2:D1000,"☐ 未完成") | D2: =B2/(B2+C2)
A3: 2026-11 | B3: =COUNTIF('2026-11'!D2:D1000,"☑ 已完成") | C3: =COUNTIF('2026-11'!D2:D1000,"☐ 未完成") | D3: =B3/(B3+C3)
A4: 2026-12 | B4: =COUNTIF('2026-12'!D2:D1000,"☑ 已完成") | C4: =COUNTIF('2026-12'!D2:D1000,"☐ 未完成") | D4: =B4/(B4+C4)
A5: 2027-01 | B5: =COUNTIF('2027-01'!D2:D1000,"☑ 已完成") | C5: =COUNTIF('2027-01'!D2:D1000,"☐ 未完成") | D5: =B5/(B5+C5)
A6: 2027-02 | B6: =COUNTIF('2027-02'!D2:D1000,"☑ 已完成") | C6: =COUNTIF('2027-02'!D2:D1000,"☐ 未完成") | D6: =B6/(B6+C6)
A7: 2027-03 | B7: =COUNTIF('2027-03'!D2:D1000,"☑ 已完成") | C7: =COUNTIF('2027-03'!D2:D1000,"☐ 未完成") | D7: =B7/(B7+C7)
A8: 2027-04 | B8: =COUNTIF('2027-04'!D2:D1000,"☑ 已完成") | C8: =COUNTIF('2027-04'!D2:D1000,"☐ 未完成") | D8: =B8/(B8+C8)
A9: 合计 | B9: =SUM(B2:B8) | C9: =SUM(C2:C8) | D9: =B9/(B9+C9)
A11: 任务倒计时
A12: 考试 | B12: 日期 | C12: 剩余天数
A13: CET4 | B13: 2026-12-12 | C13: =DATE(2026,12,12)-TODAY()
A14: 专升本 | B14: 2027-04-17 | C14: =DATE(2027,4,17)-TODAY()

Sheet 2026-10
A1: 日期 | B1: 星期 | C1: 计划事项 | D1: 任务完成 | E1: 完成率 | F1: 实际完成时间 | G1: 备注
A2: 2026-10-02 | B2: 周五 | C2: 1.高等数学（30分钟）：同济第1章·函数与极限 §1.1（约P1–11）·概念理解+例题精做+库课18套2题（库课第1套） | D2: ☐ 未完成 | E2: =COUNTIF(D2:D8,"☑ 已完成")/COUNTA(C2:C8)
C3: 2.专升本英语（30分钟）：锐树网课《入门课》精看+笔记标注→库课2000题词汇语法约15题 | D3: ☐ 未完成
C4: 3.四级阅读（45分钟）：新东方Unit1·Passage1-2限时(8min/篇) | D4: ☐ 未完成
C5: 4.四级听力（30分钟）：新东方Day1·短新闻+长对话 | D5: ☐ 未完成
C6: 5.词汇（45分钟）：不背单词APP四级词本新35词+复习（主动回忆法） | D6: ☐ 未完成
C7: 6.写作翻译（30分钟）：闪过真题·写作模板背诵+仿写1篇 | D7: ☐ 未完成
C8: 7.机动（30分钟）：整理高数错因(概念/计算/审题分类) | D8: ☐ 未完成
A9: 2026-10-03 | B9: 周六 | C9: 1.高等数学（30分钟）：复习第1章·函数与极限 §1.1（约P1–11）→复习对应A日内容+库课18套2道新大题（库课第1套） | D9: ☐ 未完成 | E9: =COUNTIF(D9:D14,"☑ 已完成")/COUNTA(C9:C14)
C10: 2.专升本英语（30分钟）：库课2000题词汇语法·第1-5题巩固+错题标注 | D10: ☐ 未完成
C11: 3.四级阅读（60分钟）：新东方Unit1·Passage1-3限时+生词复习 | D11: ☐ 未完成
C12: 4.四级听力（60分钟）：新东方Day1·完整训练+影子跟读 | D12: ☐ 未完成
C13: 5.词汇（45分钟）：不背单词APP四级词本新35词+复习（本周新词巩固） | D13: ☐ 未完成
C14: 6.写作翻译（15分钟）：闪过真题·翻译练习(英译汉5句) | D14: ☐ 未完成
A15: 2026-10-04 | B15: 周日 | C15: 1.数学模考：同济已学章节阶段自测(总习题+已学库课题)完整卷2小时估分 | D15: ☐ 未完成 | E15: =COUNTIF(D15:D16,"☑ 已完成")/COUNTA(C15:C16) | G15: 模考日
C16: 2.错题归因+周复盘+下周计划+进度自查 | D16: ☐ 未完成
A17: 2026-10-05 | B17: 周一 | C17: 1.高等数学（30分钟）：同济第1章·函数与极限 §1.2（约P11–21）·续讲精做+例题演练+库课18套2题（库课第1套） | D17: ☐ 未完成 | E17: =COUNTIF(D17:D23,"☑ 已完成")/COUNTA(C17:C23)
C18: 2.专升本英语（30分钟）：锐树网课《名词(一)(二)》精看+笔记标注→库课2000题词汇语法约15题 | D18: ☐ 未完成
C19: 3.四级阅读（45分钟）：新东方Unit2·Passage1-2限时(8min/篇) | D19: ☐ 未完成
C20: 4.四级听力（30分钟）：新东方Day2·短文理解+讲座 | D20: ☐ 未完成
C21: 5.词汇（45分钟）：不背单词APP四级词本新35词+复习（错词清零+标记） | D21: ☐ 未完成
C22: 6.写作翻译（30分钟）：闪过真题·翻译练习(汉译英5句) | D22: ☐ 未完成
C23: 7.机动（30分钟）：锐树网课笔记回顾+语法考点整理 | D23: ☐ 未完成
A24: 2026-10-06 | B24: 周二 | C24: 1.高等数学（30分钟）：复习第1章·函数与极限 §1.2（约P11–21）→概念公式默写+库课18套2道计算题（库课第1套） | D24: ☐ 未完成 | E24: =COUNTIF(D24:D29,"☑ 已完成")/COUNTA(C24:C29)
C25: 2.专升本英语（30分钟）：库课2000题词汇语法·第6-10题错题重做 | D25: ☐ 未完成
C26: 3.四级阅读（60分钟）：新东方Unit2·Passage1-3限时+生词复习 | D26: ☐ 未完成
C27: 4.四级听力（60分钟）：新东方Day2·完整训练+影子跟读 | D27: ☐ 未完成
C28: 5.词汇（45分钟）：不背单词APP四级词本新35词+复习（默写本听写验证） | D28: ☐ 未完成
C29: 6.写作翻译（15分钟）：闪过真题·写作模板回顾+限时写作1篇 | D29: ☐ 未完成
A30: 2026-10-07 | B30: 周三 | C30: 1.高等数学（30分钟）：同济第1章·函数与极限 §1.3（约P21–30）·课后习题+综合练习+库课18套2题（库课第1套） | D30: ☐ 未完成 | E30: =COUNTIF(D30:D36,"☑ 已完成")/COUNTA(C30:C36)
C31: 2.专升本英语（30分钟）：锐树网课《入门课＋名词(一)(二)》难点回看+综合练习→库课2000题词汇语法约15题 | D31: ☐ 未完成
C32: 3.四级阅读（45分钟）：Unit1-2·错题重做2篇 | D32: ☐ 未完成
C33: 4.四级听力（30分钟）：Day1-2·错题重听+影子跟读 | D33: ☐ 未完成
C34: 5.词汇（45分钟）：不背单词APP四级词本新35词+复习（生词重点巩固） | D34: ☐ 未完成
C35: 6.写作翻译（30分钟）：闪过真题·写作+翻译综合练习 | D35: ☐ 未完成
C36: 7.机动（30分钟）：进度自查+错题归因+改进计划 | D36: ☐ 未完成
A37: 2026-10-08 | B37: 周四 | C37: 1.高等数学（30分钟）：复习第1章·函数与极限 §1.3（约P21–30）→综合复习+库课18套错题重做（库课第1套） | D37: ☐ 未完成 | E37: =COUNTIF(D37:D42,"☑ 已完成")/COUNTA(C37:C42)
C38: 2.专升本英语（30分钟）：库课2000题词汇语法·第11-15题+本周错题总复习 | D38: ☐ 未完成
C39: 3.四级阅读（60分钟）：Unit1-2·限时4篇+错题分析 | D39: ☐ 未完成
C40: 4.四级听力（60分钟）：Day1-2·关键词默写+跟读 | D40: ☐ 未完成
...

Sheet 2026-11
A1: 日期 | B1: 星期 | C1: 计划事项 | D1: 任务完成 | E1: 完成率 | F1: 实际完成时间 | G1: 备注
A2: 2026-11-01 | B2: 周日 | C2: 1.数学模考：同济已学章节阶段自测(总习题+已学库课题)完整卷2小时估分 | D2: ☐ 未完成 | E2: =COUNTIF(D2:D3,"☑ 已完成")/COUNTA(C2:C3) | G2: 模考日
C3: 2.错题归因+周复盘+下周计划+进度自查 | D3: ☐ 未完成
A4: 2026-11-02 | B4: 周一 | C4: 1.高等数学（30分钟）：同济第3章·中值定理与导数应用 §3.2（约P105–112）·续讲精做+例题演练+库课18套2题（库课第5套） | D4: ☐ 未完成 | E4: =COUNTIF(D4:D10,"☑ 已完成")/COUNTA(C4:C10)
C5: 2.专升本英语（30分钟）：锐树网课《时态语态(一)(二)》精看+笔记标注→库课2000题词汇语法约15题 | D5: ☐ 未完成
C6: 3.四级阅读（45分钟）：新东方Unit10·Passage1-2限时(8min/篇) | D6: ☐ 未完成
C7: 4.四级听力（30分钟）：新东方Day10·短文理解+讲座 | D7: ☐ 未完成
C8: 5.词汇（45分钟）：不背单词APP四级词本新35词+复习（错词清零+标记） | D8: ☐ 未完成
C9: 6.写作翻译（30分钟）：闪过真题·翻译练习(汉译英5句) | D9: ☐ 未完成
C10: 7.机动（30分钟）：锐树网课笔记回顾+语法考点整理 | D10: ☐ 未完成
A11: 2026-11-03 | B11: 周二 | C11: 1.高等数学（30分钟）：复习第3章·中值定理与导数应用 §3.2（约P105–112）→概念公式默写+库课18套2道计算题（库课第5套） | D11: ☐ 未完成 | E11: =COUNTIF(D11:D16,"☑ 已完成")/COUNTA(C11:C16)
C12: 2.专升本英语（30分钟）：库课2000题词汇语法·第6-10题错题重做 | D12: ☐ 未完成
C13: 3.四级阅读（60分钟）：新东方Unit10·Passage1-3限时+生词复习 | D13: ☐ 未完成
C14: 4.四级听力（60分钟）：新东方Day10·完整训练+影子跟读 | D14: ☐ 未完成
C15: 5.词汇（45分钟）：不背单词APP四级词本新35词+复习（默写本听写验证） | D15: ☐ 未完成
C16: 6.写作翻译（15分钟）：闪过真题·写作模板回顾+限时写作1篇 | D16: ☐ 未完成
A17: 2026-11-04 | B17: 周三 | C17: 1.高等数学（30分钟）：同济第3章·中值定理与导数应用 §3.1–2(全节综合)（约P112–120）·课后习题+综合练习+库课18套2题（库课第5套） | D17: ☐ 未完成 | E17: =COUNTIF(D17:D23,"☑ 已完成")/COUNTA(C17:C23)
C18: 2.专升本英语（30分钟）：锐树网课《动词的分类(二)＋时态语态(一)(二)》难点回看+综合练习→库课2000题词汇语法约15题 | D18: ☐ 未完成
C19: 3.四级阅读（45分钟）：Unit9-10·错题重做2篇 | D19: ☐ 未完成
C20: 4.四级听力（30分钟）：Day9-10·错题重听+影子跟读 | D20: ☐ 未完成
C21: 5.词汇（45分钟）：不背单词APP四级词本新35词+复习（生词重点巩固） | D21: ☐ 未完成
C22: 6.写作翻译（30分钟）：闪过真题·写作+翻译综合练习 | D22: ☐ 未完成
C23: 7.机动（30分钟）：进度自查+错题归因+改进计划 | D23: ☐ 未完成
A24: 2026-11-05 | B24: 周四 | C24: 1.高等数学（30分钟）：复习第3章·中值定理与导数应用 §3.1–2(全节综合)（约P112–120）→综合复习+库课18套错题重做（库课第5套） | D24: ☐ 未完成 | E24: =COUNTIF(D24:D29,"☑ 已完成")/COUNTA(C24:C29)
C25: 2.专升本英语（30分钟）：库课2000题词汇语法·第11-15题+本周错题总复习 | D25: ☐ 未完成
C26: 3.四级阅读（60分钟）：Unit9-10·限时4篇+错题分析 | D26: ☐ 未完成
C27: 4.四级听力（60分钟）：Day9-10·关键词默写+跟读 | D27: ☐ 未完成
C28: 5.词汇（45分钟）：不背单词APP四级词本新35词+复习（本周词汇总复习） | D28: ☐ 未完成
C29: 6.写作翻译（15分钟）：闪过真题·翻译练习(英译汉5句) | D29: ☐ 未完成
A30: 2026-11-06 | B30: 周五 | C30: 1.高等数学（30分钟）：同济第3章 §3.3（约P120–127）·概念理解+例题精做+库课18套2题（库课第6套） | D30: ☐ 未完成 | E30: =COUNTIF(D30:D36,"☑ 已完成")/COUNTA(C30:C36)
C31: 2.专升本英语（30分钟）：锐树网课《非谓语动词(一)(二)》精看+笔记标注→库课2000题词汇语法约15题 | D31: ☐ 未完成
C32: 3.四级阅读（45分钟）：新东方Unit11·Passage1-2限时(8min/篇) | D32: ☐ 未完成
C33: 4.四级听力（30分钟）：新东方Day11·短新闻+长对话 | D33: ☐ 未完成
C34: 5.词汇（45分钟）：不背单词APP四级词本新35词+复习（主动回忆法） | D34: ☐ 未完成
C35: 6.写作翻译（30分钟）：闪过真题·写作模板背诵+仿写1篇 | D35: ☐ 未完成
C36: 7.机动（30分钟）：整理高数错因(概念/计算/审题分类) | D36: ☐ 未完成
A37: 2026-11-07 | B37: 周六 | C37: 1.高等数学（30分钟）：复习第3章 §3.3（约P120–127）→复习对应A日内容+库课18套2道新大题（库课第6套） | D37: ☐ 未完成 | E37: =COUNTIF(D37:D42,"☑ 已完成")/COUNTA(C37:C42)
C38: 2.专升本英语（30分钟）：库课2000题词汇语法·第1-5题巩固+错题标注 | D38: ☐ 未完成
C39: 3.四级阅读（60分钟）：新东方Unit11·Passage1-3限时+生词复习 | D39: ☐ 未完成
C40: 4.四级听力（60分钟）：新东方Day11·完整训练+影子跟读 | D40: ☐ 未完成
...

Sheet 2026-12
A1: 日期 | B1: 星期 | C1: 计划事项 | D1: 任务完成 | E1: 完成率 | F1: 实际完成时间 | G1: 备注
A2: 2026-12-01 | B2: 周二 | C2: 1.高等数学（30分钟）：复习第4章·不定积分 §4.4（约P178–184）→概念公式默写+库课18套2道计算题（库课第9套） | D2: ☐ 未完成 | E2: =COUNTIF(D2:D7,"☑ 已完成")/COUNTA(C2:C7)
C3: 2.专升本英语（30分钟）：库课2000题阅读·第6-10题错题重做 | D3: ☐ 未完成
C4: 3.四级阅读（60分钟）：新东方Unit18·Passage1-3限时+生词复习 | D4: ☐ 未完成
C5: 4.四级听力（60分钟）：新东方Day18·完整训练+影子跟读 | D5: ☐ 未完成
C6: 5.词汇（45分钟）：不背单词APP四级词本新35词+复习，闪过默写本20词（默写本听写验证） | D6: ☐ 未完成
C7: 6.写作翻译（15分钟）：闪过真题·写作模板回顾+限时写作1篇 | D7: ☐ 未完成
A8: 2026-12-02 | B8: 周三 | C8: 1.高等数学（30分钟）：同济第4章·不定积分 §4.3–4(全节综合)（约P184–190）·课后习题+综合练习+库课18套2题（库课第9套） | D8: ☐ 未完成 | E8: =COUNTIF(D8:D14,"☑ 已完成")/COUNTA(C8:C14)
C9: 2.专升本英语（30分钟）：锐树网课《习题精析·连词成句》难点回看+综合练习→库课2000题阅读约15题 | D9: ☐ 未完成
C10: 3.四级阅读（45分钟）：Unit17-18·错题重做2篇 | D10: ☐ 未完成
C11: 4.四级听力（30分钟）：Day17-18·错题重听+影子跟读 | D11: ☐ 未完成
C12: 5.词汇（45分钟）：不背单词APP四级词本新35词+复习，闪过默写本20词（生词重点巩固） | D12: ☐ 未完成
C13: 6.写作翻译（30分钟）：闪过真题·写作+翻译综合练习 | D13: ☐ 未完成
C14: 7.机动（30分钟）：进度自查+错题归因+改进计划 | D14: ☐ 未完成
A15: 2026-12-03 | B15: 周四 | C15: 1.高等数学（30分钟）：复习第4章·不定积分 §4.3–4(全节综合)（约P184–190）→综合复习+库课18套错题重做（库课第9套） | D15: ☐ 未完成 | E15: =COUNTIF(D15:D20,"☑ 已完成")/COUNTA(C15:C20)
C16: 2.专升本英语（30分钟）：库课2000题阅读·第11-15题+本周错题总复习 | D16: ☐ 未完成
C17: 3.四级阅读（60分钟）：Unit17-18·限时4篇+错题分析 | D17: ☐ 未完成
C18: 4.四级听力（60分钟）：Day17-18·关键词默写+跟读 | D18: ☐ 未完成
C19: 5.词汇（45分钟）：不背单词APP四级词本新35词+复习，闪过默写本20词（本周词汇总复习） | D19: ☐ 未完成
C20: 6.写作翻译（15分钟）：闪过真题·翻译练习(英译汉5句) | D20: ☐ 未完成
A21: 2026-12-04 | B21: 周五 | C21: 1.高等数学（30分钟）：同济第4章综合复习+例题（约P190–192）·概念理解+例题精做+库课18套2题（库课第10套） | D21: ☐ 未完成 | E21: =COUNTIF(D21:D27,"☑ 已完成")/COUNTA(C21:C27)
C22: 2.专升本英语（30分钟）：锐树网课《连词成句(三)(四)》精看+笔记标注→库课2000题阅读约15题 | D22: ☐ 未完成
C23: 3.四级阅读（45分钟）：新东方Unit19·Passage1-2限时(8min/篇) | D23: ☐ 未完成
C24: 4.四级听力（30分钟）：新东方Day19·短新闻+长对话 | D24: ☐ 未完成
C25: 5.词汇（45分钟）：不背单词APP四级词本新35词+复习，闪过默写本20词（主动回忆法） | D25: ☐ 未完成
C26: 6.写作翻译（30分钟）：闪过真题·写作模板背诵+仿写1篇 | D26: ☐ 未完成
C27: 7.机动（30分钟）：整理高数错因(概念/计算/审题分类) | D27: ☐ 未完成
A28: 2026-12-05 | B28: 周六 | C28: 1.高等数学（30分钟）：复习第4章综合复习+例题（约P190–192）→复习对应A日内容+库课18套2道新大题（库课第10套） | D28: ☐ 未完成 | E28: =COUNTIF(D28:D33,"☑ 已完成")/COUNTA(C28:C33)
C29: 2.专升本英语（30分钟）：库课2000题阅读·第1-5题巩固+错题标注 | D29: ☐ 未完成
C30: 3.四级阅读（60分钟）：新东方Unit19·Passage1-3限时+生词复习 | D30: ☐ 未完成
C31: 4.四级听力（60分钟）：新东方Day19·完整训练+影子跟读 | D31: ☐ 未完成
C32: 5.词汇（45分钟）：不背单词APP四级词本新35词+复习，闪过默写本20词（本周新词巩固） | D32: ☐ 未完成
C33: 6.写作翻译（15分钟）：闪过真题·翻译练习(英译汉5句) | D33: ☐ 未完成
A34: 2026-12-06 | B34: 周日 | C34: 1.四级模考：闪过真题第5套完整真题2小时按710分估分 | D34: ☐ 未完成 | E34: =COUNTIF(D34:D35,"☑ 已完成")/COUNTA(C34:C35) | G34: 模考日
C35: 2.错题归因+周复盘+下周计划 | D35: ☐ 未完成
A36: 2026-12-07 | B36: 周一 | C36: 1.高等数学（30分钟）：同济第4章综合复习+例题（约P192–194）·续讲精做+例题演练+库课18套2题（库课第10套） | D36: ☐ 未完成 | E36: =COUNTIF(D36:D42,"☑ 已完成")/COUNTA(C36:C42)
C37: 2.专升本英语（30分钟）：锐树网课《篇章填空(一)》精看+笔记标注→库课2000题阅读约15题 | D37: ☐ 未完成
C38: 3.四级阅读（45分钟）：新东方Unit20·Passage1-2限时(8min/篇) | D38: ☐ 未完成
C39: 4.四级听力（30分钟）：新东方Day20·短文理解+讲座 | D39: ☐ 未完成
C40: 5.词汇（45分钟）：不背单词APP四级词本新35词+复习，闪过默写本20词（错词清零+标记） | D40: ☐ 未完成
...

Sheet 2027-01
A1: 日期 | B1: 星期 | C1: 计划事项 | D1: 任务完成 | E1: 完成率 | F1: 实际完成时间 | G1: 备注
A2: 2027-01-01 | B2: 周五 | C2: 【节假日·约2小时】1.词汇：不背单词APP转专升本词本+高频词（不变） | D2: ☐ 未完成 | E2: =COUNTIF(D2:D4,"☑ 已完成")/COUNTA(C2:C4) | G2: 节假日·减半(约2小时)
C3: 2.高等数学：只复习本周错题40分钟 | D3: ☐ 未完成
C4: 3.专升本英语：库课2000题错题回顾30分钟 | D4: ☐ 未完成
A5: 2027-01-02 | B5: 周六 | C5: 1.高等数学（75分钟）：复习第5章综合+库课章节汇总→复习对应A日内容+库课18套2道新大题（库课第14套） | D5: ☐ 未完成 | E5: =COUNTIF(D5:D8,"☑ 已完成")/COUNTA(C5:C8)
C6: 2.专升本英语（90分钟）：锐树网课回看+库课2000题翻译·第1-5题巩固+错题标注 | D6: ☐ 未完成
C7: 3.专升本英语完形填空专项(库课完形)（45分钟） | D7: ☐ 未完成
C8: 4.词汇（30分钟）：不背单词APP转专升本词本+高频词（新词巩固） | D8: ☐ 未完成
A9: 2027-01-03 | B9: 周日 | C9: 1.专升本英语模考：真题综合（约2小时） | D9: ☐ 未完成 | E9: =COUNTIF(D9:D10,"☑ 已完成")/COUNTA(C9:C10) | G9: 模考日
C10: 2.错题归因+周复盘 | D10: ☐ 未完成
A11: 2027-01-04 | B11: 周一 | C11: 1.高等数学（90分钟）：同济第5章综合+库课章节汇总·概念理解+例题精做+库课18套2题（库课第14套） | D11: ☐ 未完成 | E11: =COUNTIF(D11:D14,"☑ 已完成")/COUNTA(C11:C14)
C12: 2.专升本英语（75分钟）：锐树网课《阅读问答(二)(三)》精看+笔记标注→库课2000题翻译约25题 | D12: ☐ 未完成
C13: 3.专升本英语阅读专项(库课阅读理解)（45分钟） | D13: ☐ 未完成
C14: 4.词汇（30分钟）：不背单词APP转专升本词本+高频词（主动回忆） | D14: ☐ 未完成
A15: 2027-01-05 | B15: 周二 | C15: 1.高等数学（75分钟）：复习第5章综合+库课章节汇总→概念公式默写+库课18套2道计算题（库课第14套） | D15: ☐ 未完成 | E15: =COUNTIF(D15:D18,"☑ 已完成")/COUNTA(C15:C18)
C16: 2.专升本英语（90分钟）：锐树网课回看+库课2000题翻译·第6-10题错题重做 | D16: ☐ 未完成
C17: 3.专升本英语写作专项(库课写作)（45分钟） | D17: ☐ 未完成
C18: 4.词汇（30分钟）：不背单词APP转专升本词本+高频词（听写验证） | D18: ☐ 未完成
A19: 2027-01-06 | B19: 周三 | C19: 1.高等数学（90分钟）：同济第5章综合+库课章节汇总·续讲精做+例题演练+库课18套2题（库课第14套） | D19: ☐ 未完成 | E19: =COUNTIF(D19:D22,"☑ 已完成")/COUNTA(C19:C22)
C20: 2.专升本英语（75分钟）：锐树网课《英译汉》精看+笔记标注→库课2000题翻译约25题 | D20: ☐ 未完成
C21: 3.专升本英语翻译专项(库课翻译练习)（45分钟） | D21: ☐ 未完成
C22: 4.词汇（30分钟）：不背单词APP转专升本词本+高频词（错词巩固） | D22: ☐ 未完成
A23: 2027-01-07 | B23: 周四 | C23: 1.高等数学（75分钟）：复习第5章综合+库课章节汇总→综合复习+库课18套错题重做（库课第14套） | D23: ☐ 未完成 | E23: =COUNTIF(D23:D26,"☑ 已完成")/COUNTA(C23:C26)
C24: 2.专升本英语（90分钟）：锐树网课回看+库课2000题翻译·第11-15题+本周错题总复习 | D24: ☐ 未完成
C25: 3.专升本英语完形+写作综合练习（45分钟） | D25: ☐ 未完成
C26: 4.词汇（30分钟）：不背单词APP转专升本词本+高频词（总复习） | D26: ☐ 未完成
A27: 2027-01-08 | B27: 周五 | C27: 1.高等数学（90分钟）：同济第6章·微分方程 §6.1（约P260–265）·概念理解+例题精做+库课18套2题（库课第15套） | D27: ☐ 未完成 | E27: =COUNTIF(D27:D30,"☑ 已完成")/COUNTA(C27:C30)
C28: 2.专升本英语（75分钟）：锐树网课《汉译英》精看+笔记标注→库课2000题写作约25题 | D28: ☐ 未完成
C29: 3.专升本英语阅读专项(库课阅读理解)（45分钟） | D29: ☐ 未完成
C30: 4.词汇（30分钟）：不背单词APP转专升本词本+高频词（主动回忆） | D30: ☐ 未完成
A31: 2027-01-09 | B31: 周六 | C31: 1.高等数学（75分钟）：复习第6章·微分方程 §6.1（约P260–265）→复习对应A日内容+库课18套2道新大题（库课第15套） | D31: ☐ 未完成 | E31: =COUNTIF(D31:D34,"☑ 已完成")/COUNTA(C31:C34)
C32: 2.专升本英语（90分钟）：锐树网课回看+库课2000题写作·第1-5题巩固+错题标注 | D32: ☐ 未完成
C33: 3.专升本英语完形填空专项(库课完形)（45分钟） | D33: ☐ 未完成
C34: 4.词汇（30分钟）：不背单词APP转专升本词本+高频词（新词巩固） | D34: ☐ 未完成
A35: 2027-01-10 | B35: 周日 | C35: 1.专升本数学模考：库课18套完整卷第5套2小时估分 | D35: ☐ 未完成 | E35: =COUNTIF(D35:D36,"☑ 已完成")/COUNTA(C35:C36) | G35: 模考日
C36: 2.错题归因+周复盘 | D36: ☐ 未完成
A37: 2027-01-11 | B37: 周一 | C37: 1.高等数学（90分钟）：同济第6章·微分方程 §6.2（约P265–270）·续讲精做+例题演练+库课18套2题（库课第15套） | D37: ☐ 未完成 | E37: =COUNTIF(D37:D40,"☑ 已完成")/COUNTA(C37:C40)
C38: 2.专升本英语（75分钟）：锐树网课《写作(提纲/命题图景)》精看+笔记标注→库课2000题写作约25题 | D38: ☐ 未完成
C39: 3.专升本英语翻译专项(库课翻译练习)（45分钟） | D39: ☐ 未完成
C40: 4.词汇（30分钟）：不背单词APP转专升本词本+高频词（错词巩固） | D40: ☐ 未完成
...

Sheet 2027-02
A1: 日期 | B1: 星期 | C1: 计划事项 | D1: 任务完成 | E1: 完成率 | F1: 实际完成时间 | G1: 备注
A2: 2027-02-01 | B2: 周一 | C2: 1.高等数学（90分钟）：同济一轮复习第1–4章+错题+库课18套2题（教材二刷·第1-4章） | D2: ☐ 未完成 | E2: =COUNTIF(D2:D5,"☑ 已完成")/COUNTA(C2:C5)
C3: 2.专升本英语（75分钟）：锐树网课《朱老师版·动词专项(二)(三)(四)＋章节练习·动词20题》二刷+库课2000题专项综合练习 | D3: ☐ 未完成
C4: 3.专升本英语阅读+翻译专项（45分钟） | D4: ☐ 未完成
C5: 4.词汇（30分钟）：不背单词APP转专升本词本+高频词 | D5: ☐ 未完成
A6: 2027-02-02 | B6: 周二 | C6: 1.高等数学（75分钟）：错题回顾+库课18套2道新大题+教材回读（第1-4章） | D6: ☐ 未完成 | E6: =COUNTIF(D6:D9,"☑ 已完成")/COUNTA(C6:C9)
C7: 2.专升本英语（90分钟）：库课2000题专项综合约15题巩固+锐树网课二刷回看 | D7: ☐ 未完成
C8: 3.专升本英语完形+写作专项（45分钟） | D8: ☐ 未完成
C9: 4.词汇（30分钟）：不背单词APP转专升本词本+高频词 | D9: ☐ 未完成
A10: 2027-02-03 | B10: 周三 | C10: 1.高等数学（90分钟）：同济一轮复习第1–4章+错题+库课18套2题（教材二刷·第1-4章） | D10: ☐ 未完成 | E10: =COUNTIF(D10:D13,"☑ 已完成")/COUNTA(C10:C13)
C11: 2.专升本英语（75分钟）：锐树网课《朱老师版·动词专项(二)(三)(四)＋章节练习·动词20题》二刷+库课2000题专项综合练习 | D11: ☐ 未完成
C12: 3.专升本英语阅读+翻译专项（45分钟） | D12: ☐ 未完成
C13: 4.词汇（30分钟）：不背单词APP转专升本词本+高频词 | D13: ☐ 未完成
A14: 2027-02-04 | B14: 周四 | C14: 1.高等数学（75分钟）：错题回顾+库课18套2道新大题+教材回读（第1-4章） | D14: ☐ 未完成 | E14: =COUNTIF(D14:D17,"☑ 已完成")/COUNTA(C14:C17)
C15: 2.专升本英语（90分钟）：库课2000题专项综合约15题巩固+锐树网课二刷回看 | D15: ☐ 未完成
C16: 3.专升本英语完形+写作专项（45分钟） | D16: ☐ 未完成
C17: 4.词汇（30分钟）：不背单词APP转专升本词本+高频词 | D17: ☐ 未完成
A18: 2027-02-05 | B18: 周五 | C18: 【节假日·约2小时】1.词汇：不背单词APP转专升本词本+高频词（不变） | D18: ☐ 未完成 | E18: =COUNTIF(D18:D20,"☑ 已完成")/COUNTA(C18:C20) | G18: 节假日·减半(约2小时)
C19: 2.高等数学：只复习本周错题40分钟 | D19: ☐ 未完成
C20: 3.专升本英语：库课2000题错题回顾30分钟 | D20: ☐ 未完成
A21: 2027-02-06 | B21: 周六 | C21: 【节假日·约2小时】1.词汇：不背单词APP转专升本词本+高频词（不变） | D21: ☐ 未完成 | E21: =COUNTIF(D21:D23,"☑ 已完成")/COUNTA(C21:C23) | G21: 节假日·减半(约2小时)
C22: 2.高等数学：只复习本周错题40分钟 | D22: ☐ 未完成
C23: 3.专升本英语：库课2000题错题回顾30分钟 | D23: ☐ 未完成
A24: 2027-02-07 | B24: 周日 | C24: 【节假日·约2小时】1.词汇：不背单词APP转专升本词本+高频词（不变） | D24: ☐ 未完成 | E24: =COUNTIF(D24:D26,"☑ 已完成")/COUNTA(C24:C26) | G24: 节假日·减半(约2小时)
C25: 2.高等数学：只复习本周错题40分钟 | D25: ☐ 未完成
C26: 3.专升本英语：库课2000题错题回顾30分钟 | D26: ☐ 未完成
A27: 2027-02-08 | B27: 周一 | C27: 【节假日·约2小时】1.词汇：不背单词APP转专升本词本+高频词（不变） | D27: ☐ 未完成 | E27: =COUNTIF(D27:D29,"☑ 已完成")/COUNTA(C27:C29) | G27: 节假日·减半(约2小时)
C28: 2.高等数学：只复习本周错题40分钟 | D28: ☐ 未完成
C29: 3.专升本英语：库课2000题错题回顾30分钟 | D29: ☐ 未完成
A30: 2027-02-09 | B30: 周二 | C30: 【节假日·约2小时】1.词汇：不背单词APP转专升本词本+高频词（不变） | D30: ☐ 未完成 | E30: =COUNTIF(D30:D32,"☑ 已完成")/COUNTA(C30:C32) | G30: 节假日·减半(约2小时)
C31: 2.高等数学：只复习本周错题40分钟 | D31: ☐ 未完成
C32: 3.专升本英语：库课2000题错题回顾30分钟 | D32: ☐ 未完成
A33: 2027-02-10 | B33: 周三 | C33: 【节假日·约2小时】1.词汇：不背单词APP转专升本词本+高频词（不变） | D33: ☐ 未完成 | E33: =COUNTIF(D33:D35,"☑ 已完成")/COUNTA(C33:C35) | G33: 节假日·减半(约2小时)
C34: 2.高等数学：只复习本周错题40分钟 | D34: ☐ 未完成
C35: 3.专升本英语：库课2000题错题回顾30分钟 | D35: ☐ 未完成
A36: 2027-02-11 | B36: 周四 | C36: 【节假日·约2小时】1.词汇：不背单词APP转专升本词本+高频词（不变） | D36: ☐ 未完成 | E36: =COUNTIF(D36:D38,"☑ 已完成")/COUNTA(C36:C38) | G36: 节假日·减半(约2小时)
C37: 2.高等数学：只复习本周错题40分钟 | D37: ☐ 未完成
C38: 3.专升本英语：库课2000题错题回顾30分钟 | D38: ☐ 未完成
A39: 2027-02-12 | B39: 周五 | C39: 1.高等数学（90分钟）：同济库课18套第4–9套+高数教材二刷(第1–4章)+库课18套2题（教材二刷·第1-4章） | D39: ☐ 未完成 | E39: =COUNTIF(D39:D42,"☑ 已完成")/COUNTA(C39:C42)
C40: 2.专升本英语（75分钟）：锐树网课《朱老师版·句子类型＋句子成分＋宾语从句＋章节练习·句子类型2+成分1+宾语从句26题》二刷+库课2000题专项综合练习 | D40: ☐ 未完成
...

Sheet 2027-03
A1: 日期 | B1: 星期 | C1: 计划事项 | D1: 任务完成 | E1: 完成率 | F1: 实际完成时间 | G1: 备注
A2: 2027-03-01 | B2: 周一 | C2: 1.高等数学（90分钟）：同济库课18套第13–15套+全真模考+库课18套2题（教材二刷·错题） | D2: ☐ 未完成 | E2: =COUNTIF(D2:D5,"☑ 已完成")/COUNTA(C2:C5)
C3: 2.专升本英语（75分钟）：锐树网课《朱老师版·阅读方法＋主旨大意＋推理题＋细节理解(一)(二)＋章节练习·细节理解21题+翻译23题》二刷+库课2000题专项综合练习 | D3: ☐ 未完成
C4: 3.专升本英语阅读+翻译专项（45分钟） | D4: ☐ 未完成
C5: 4.词汇（30分钟）：不背单词APP转专升本词本+高频词 | D5: ☐ 未完成
A6: 2027-03-02 | B6: 周二 | C6: 1.高等数学（75分钟）：错题回顾+库课18套2道新大题+教材回读（错题） | D6: ☐ 未完成 | E6: =COUNTIF(D6:D9,"☑ 已完成")/COUNTA(C6:C9)
C7: 2.专升本英语（90分钟）：库课2000题专项综合约15题巩固+锐树网课二刷回看 | D7: ☐ 未完成
C8: 3.专升本英语完形+写作专项（45分钟） | D8: ☐ 未完成
C9: 4.词汇（30分钟）：不背单词APP转专升本词本+高频词 | D9: ☐ 未完成
A10: 2027-03-03 | B10: 周三 | C10: 1.高等数学（90分钟）：同济库课18套第13–15套+全真模考+库课18套2题（教材二刷·错题） | D10: ☐ 未完成 | E10: =COUNTIF(D10:D13,"☑ 已完成")/COUNTA(C10:C13)
C11: 2.专升本英语（75分钟）：锐树网课《朱老师版·阅读方法＋主旨大意＋推理题＋细节理解(一)(二)＋章节练习·细节理解21题+翻译23题》二刷+库课2000题专项综合练习 | D11: ☐ 未完成
C12: 3.专升本英语阅读+翻译专项（45分钟） | D12: ☐ 未完成
C13: 4.词汇（30分钟）：不背单词APP转专升本词本+高频词 | D13: ☐ 未完成
A14: 2027-03-04 | B14: 周四 | C14: 1.高等数学（75分钟）：错题回顾+库课18套2道新大题+教材回读（错题） | D14: ☐ 未完成 | E14: =COUNTIF(D14:D17,"☑ 已完成")/COUNTA(C14:C17)
C15: 2.专升本英语（90分钟）：库课2000题专项综合约15题巩固+锐树网课二刷回看 | D15: ☐ 未完成
C16: 3.专升本英语完形+写作专项（45分钟） | D16: ☐ 未完成
C17: 4.词汇（30分钟）：不背单词APP转专升本词本+高频词 | D17: ☐ 未完成
A18: 2027-03-05 | B18: 周五 | C18: 1.高等数学（90分钟）：同济冲刺模考+易错专练(极限/导数/积分)+高数教材二刷(全章)+库课18套2题（教材二刷·全章） | D18: ☐ 未完成 | E18: =COUNTIF(D18:D21,"☑ 已完成")/COUNTA(C18:C21)
C19: 2.专升本英语（75分钟）：锐树网课《二刷·宋版词法动词＋从句特殊句式(易错)》二刷+库课2000题二刷·错题练习 | D19: ☐ 未完成
C20: 3.专升本英语阅读+翻译专项（45分钟） | D20: ☐ 未完成
C21: 4.词汇（30分钟）：不背单词APP转专升本词本+高频词 | D21: ☐ 未完成
A22: 2027-03-06 | B22: 周六 | C22: 1.高等数学（75分钟）：错题回顾+库课18套2道新大题+教材回读（全章） | D22: ☐ 未完成 | E22: =COUNTIF(D22:D25,"☑ 已完成")/COUNTA(C22:C25)
C23: 2.专升本英语（90分钟）：库课2000题二刷·错题约15题巩固+锐树网课二刷回看 | D23: ☐ 未完成
C24: 3.专升本英语完形+写作专项（45分钟） | D24: ☐ 未完成
C25: 4.词汇（30分钟）：不背单词APP转专升本词本+高频词 | D25: ☐ 未完成
A26: 2027-03-07 | B26: 周日 | C26: 1.专升本数学模考：库课18套完整卷第9套2小时估分 | D26: ☐ 未完成 | E26: =COUNTIF(D26:D27,"☑ 已完成")/COUNTA(C26:C27) | G26: 模考日
C27: 2.错题归因+周复盘 | D27: ☐ 未完成
A28: 2027-03-08 | B28: 周一 | C28: 1.高等数学（90分钟）：同济冲刺模考+易错专练(极限/导数/积分)+高数教材二刷(全章)+库课18套2题（教材二刷·全章） | D28: ☐ 未完成 | E28: =COUNTIF(D28:D31,"☑ 已完成")/COUNTA(C28:C31)
C29: 2.专升本英语（75分钟）：锐树网课《二刷·宋版词法动词＋从句特殊句式(易错)》二刷+库课2000题二刷·错题练习 | D29: ☐ 未完成
C30: 3.专升本英语阅读+翻译专项（45分钟） | D30: ☐ 未完成
C31: 4.词汇（30分钟）：不背单词APP转专升本词本+高频词 | D31: ☐ 未完成
A32: 2027-03-09 | B32: 周二 | C32: 1.高等数学（75分钟）：错题回顾+库课18套2道新大题+教材回读（全章） | D32: ☐ 未完成 | E32: =COUNTIF(D32:D35,"☑ 已完成")/COUNTA(C32:C35)
C33: 2.专升本英语（90分钟）：库课2000题二刷·错题约15题巩固+锐树网课二刷回看 | D33: ☐ 未完成
C34: 3.专升本英语完形+写作专项（45分钟） | D34: ☐ 未完成
C35: 4.词汇（30分钟）：不背单词APP转专升本词本+高频词 | D35: ☐ 未完成
A36: 2027-03-10 | B36: 周三 | C36: 1.高等数学（90分钟）：同济冲刺模考+易错专练(极限/导数/积分)+高数教材二刷(全章)+库课18套2题（教材二刷·全章） | D36: ☐ 未完成 | E36: =COUNTIF(D36:D39,"☑ 已完成")/COUNTA(C36:C39) | G36: 专升本报名窗口(参考3/10-13)
C37: 2.专升本英语（75分钟）：锐树网课《二刷·宋版词法动词＋从句特殊句式(易错)》二刷+库课2000题二刷·错题练习 | D37: ☐ 未完成
C38: 3.专升本英语阅读+翻译专项（45分钟） | D38: ☐ 未完成
C39: 4.词汇（30分钟）：不背单词APP转专升本词本+高频词 | D39: ☐ 未完成
A40: 2027-03-11 | B40: 周四 | C40: 1.高等数学（75分钟）：错题回顾+库课18套2道新大题+教材回读（全章） | D40: ☐ 未完成 | E40: =COUNTIF(D40:D43,"☑ 已完成")/COUNTA(C40:C43)
...

Sheet 2027-04
A1: 日期 | B1: 星期 | C1: 计划事项 | D1: 任务完成 | E1: 完成率 | F1: 实际完成时间 | G1: 备注
A2: 2027-04-01 | B2: 周四 | C2: 1.高等数学（75分钟）：错题回顾+库课18套2道新大题+教材回读（公式速记） | D2: ☐ 未完成 | E2: =COUNTIF(D2:D5,"☑ 已完成")/COUNTA(C2:C5)
C3: 2.专升本英语（90分钟）：库课2000题二刷·错题约15题巩固+锐树网课二刷回看 | D3: ☐ 未完成
C4: 3.专升本英语完形+写作专项（45分钟） | D4: ☐ 未完成
C5: 4.词汇（30分钟）：不背单词APP转专升本词本+高频词 | D5: ☐ 未完成
A6: 2027-04-02 | B6: 周五 | C6: 1.高等数学（90分钟）：同济全真模考冲刺+易错重做+公式速记+易错清单+库课18套2题（教材二刷·易错清单） | D6: ☐ 未完成 | E6: =COUNTIF(D6:D9,"☑ 已完成")/COUNTA(C6:C9)
C7: 2.专升本英语（75分钟）：锐树网课《三刷·非谓语/时态语态/定语从句》二刷+库课2000题二刷·错题练习 | D7: ☐ 未完成
C8: 3.专升本英语阅读+翻译专项（45分钟） | D8: ☐ 未完成
C9: 4.词汇（30分钟）：不背单词APP转专升本词本+高频词 | D9: ☐ 未完成
A10: 2027-04-03 | B10: 周六 | C10: 1.高等数学（75分钟）：错题回顾+库课18套2道新大题+教材回读（易错清单） | D10: ☐ 未完成 | E10: =COUNTIF(D10:D13,"☑ 已完成")/COUNTA(C10:C13)
C11: 2.专升本英语（90分钟）：库课2000题二刷·错题约15题巩固+锐树网课二刷回看 | D11: ☐ 未完成
C12: 3.专升本英语完形+写作专项（45分钟） | D12: ☐ 未完成
C13: 4.词汇（30分钟）：不背单词APP转专升本词本+高频词 | D13: ☐ 未完成
A14: 2027-04-04 | B14: 周日 | C14: 1.专升本数学模考：库课18套完整卷第11套2小时估分 | D14: ☐ 未完成 | E14: =COUNTIF(D14:D15,"☑ 已完成")/COUNTA(C14:C15) | G14: 模考日
C15: 2.错题归因+周复盘 | D15: ☐ 未完成
A16: 2027-04-05 | B16: 周一 | C16: 1.高等数学（90分钟）：同济全真模考冲刺+易错重做+公式速记+易错清单+库课18套2题（教材二刷·易错清单） | D16: ☐ 未完成 | E16: =COUNTIF(D16:D19,"☑ 已完成")/COUNTA(C16:C19)
C17: 2.专升本英语（75分钟）：锐树网课《三刷·非谓语/时态语态/定语从句》二刷+库课2000题二刷·错题练习 | D17: ☐ 未完成
C18: 3.专升本英语阅读+翻译专项（45分钟） | D18: ☐ 未完成
C19: 4.词汇（30分钟）：不背单词APP转专升本词本+高频词 | D19: ☐ 未完成
A20: 2027-04-06 | B20: 周二 | C20: 1.高等数学（75分钟）：错题回顾+库课18套2道新大题+教材回读（易错清单） | D20: ☐ 未完成 | E20: =COUNTIF(D20:D23,"☑ 已完成")/COUNTA(C20:C23)
C21: 2.专升本英语（90分钟）：库课2000题二刷·错题约15题巩固+锐树网课二刷回看 | D21: ☐ 未完成
C22: 3.专升本英语完形+写作专项（45分钟） | D22: ☐ 未完成
C23: 4.词汇（30分钟）：不背单词APP转专升本词本+高频词 | D23: ☐ 未完成
A24: 2027-04-07 | B24: 周三 | C24: 1.高等数学（90分钟）：同济全真模考冲刺+易错重做+公式速记+易错清单+库课18套2题（教材二刷·易错清单） | D24: ☐ 未完成 | E24: =COUNTIF(D24:D27,"☑ 已完成")/COUNTA(C24:C27)
C25: 2.专升本英语（75分钟）：锐树网课《三刷·非谓语/时态语态/定语从句》二刷+库课2000题二刷·错题练习 | D25: ☐ 未完成
C26: 3.专升本英语阅读+翻译专项（45分钟） | D26: ☐ 未完成
C27: 4.词汇（30分钟）：不背单词APP转专升本词本+高频词 | D27: ☐ 未完成
A28: 2027-04-08 | B28: 周四 | C28: 1.高等数学（75分钟）：错题回顾+库课18套2道新大题+教材回读（易错清单） | D28: ☐ 未完成 | E28: =COUNTIF(D28:D31,"☑ 已完成")/COUNTA(C28:C31)
C29: 2.专升本英语（90分钟）：库课2000题二刷·错题约15题巩固+锐树网课二刷回看 | D29: ☐ 未完成
C30: 3.专升本英语完形+写作专项（45分钟） | D30: ☐ 未完成
C31: 4.词汇（30分钟）：不背单词APP转专升本词本+高频词 | D31: ☐ 未完成
A32: 2027-04-09 | B32: 周五 | C32: 1.高等数学（90分钟）：同济考前·公式速记+易错清单回顾+库课18套2题（教材二刷·冲刺） | D32: ☐ 未完成 | E32: =COUNTIF(D32:D35,"☑ 已完成")/COUNTA(C32:C35)
C33: 2.专升本英语（75分钟）：锐树网课《冲刺·真题精讲＋模考错题回看＋翻译写作模板》二刷+库课2000题二刷·错题练习 | D33: ☐ 未完成
C34: 3.专升本英语阅读+翻译专项（45分钟） | D34: ☐ 未完成
C35: 4.词汇（30分钟）：不背单词APP转专升本词本+高频词 | D35: ☐ 未完成
A36: 2027-04-10 | B36: 周六 | C36: 1.高等数学（75分钟）：错题回顾+库课18套2道新大题+教材回读（冲刺） | D36: ☐ 未完成 | E36: =COUNTIF(D36:D39,"☑ 已完成")/COUNTA(C36:C39) | G36: 专升本候选考试日(以官方为准)
C37: 2.专升本英语（90分钟）：库课2000题二刷·错题约15题巩固+锐树网课二刷回看 | D37: ☐ 未完成
C38: 3.专升本英语完形+写作专项（45分钟） | D38: ☐ 未完成
C39: 4.词汇（30分钟）：不背单词APP转专升本词本+高频词 | D39: ☐ 未完成
A40: 2027-04-11 | B40: 周日 | C40: 1.专升本英语模考：2026年真题（约2小时） | D40: ☐ 未完成 | E40: =COUNTIF(D40:D41,"☑ 已完成")/COUNTA(C40:C41) | G40: 模考日
...
